[2024-06-12T07:10:09.160+0000] {scheduler_job_runner.py:1562} WARNING - Marking task instance <TaskInstance: spotify_final_dag.create_table scheduled__2024-06-09T15:00:00+00:00 [queued]> stuck in queued as failed. If the task instance has available retries, it will be retried.
[2024-06-12T07:10:11.161+0000] {scheduler_job_runner.py:769} ERROR - Executor reports task instance <TaskInstance: spotify_final_dag.create_table scheduled__2024-06-09T15:00:00+00:00 [queued]> finished (failed) although the task says it's queued. (Info: None) Was the task killed externally?
